Internal Server Error: /upload-and-predict/
Internal Server Error: /upload-and-predict/
Internal Server Error: /upload-and-predict/
"POST /upload-and-predict/ HTTP/1.1" 500 34
"POST /upload-and-predict/ HTTP/1.1" 500 34
"POST /upload-and-predict/ HTTP/1.1" 500 34
Internal Server Error: /upload-and-predict/
Internal Server Error: /upload-and-predict/
Internal Server Error: /upload-and-predict/
"POST /upload-and-predict/ HTTP/1.1" 500 34
"POST /upload-and-predict/ HTTP/1.1" 500 34
"POST /upload-and-predict/ HTTP/1.1" 500 34
Internal Server Error: /upload-and-predict/
Traceback (most recent call last):
  File "C:\Users\NKYA\Josiah_projects\CANCER\main\views.py", line 82, in upload_and_predict
    return JsonResponse({'error': 'Error processing the DICOM image'}, status=400)
  File "C:\Users\NKYA\Josiah_projects\Venv\afyaAI\lib\site-packages\keras\src\utils\traceback_utils.py", line 122, in error_handler
    raise e.with_traceback(filtered_tb) from None
  File "C:\Python\lib\encodings\cp1252.py", line 19, in encode
    return codecs.charmap_encode(input,self.errors,encoding_table)[0]
UnicodeEncodeError: 'charmap' codec can't encode characters in position 19-38: character maps to <undefined>

During handling of the above exception, another exception occurred:

Traceback (most recent call last):
  File "C:\Users\NKYA\Josiah_projects\Venv\afyaAI\lib\site-packages\django\core\handlers\exception.py", line 47, in inner
    response = get_response(request)
  File "C:\Users\NKYA\Josiah_projects\Venv\afyaAI\lib\site-packages\django\core\handlers\base.py", line 181, in _get_response
    response = wrapped_callback(request, *callback_args, **callback_kwargs)
  File "C:\Users\NKYA\Josiah_projects\Venv\afyaAI\lib\site-packages\django\views\decorators\csrf.py", line 54, in wrapped_view
    return view_func(*args, **kwargs)
  File "C:\Users\NKYA\Josiah_projects\CANCER\main\views.py", line 97, in upload_and_predict
    })
NameError: name 'logger' is not defined
Internal Server Error: /upload-and-predict/
Traceback (most recent call last):
  File "C:\Users\NKYA\Josiah_projects\CANCER\main\views.py", line 82, in upload_and_predict
    return JsonResponse({'error': 'Error processing the DICOM image'}, status=400)
  File "C:\Users\NKYA\Josiah_projects\Venv\afyaAI\lib\site-packages\keras\src\utils\traceback_utils.py", line 122, in error_handler
    raise e.with_traceback(filtered_tb) from None
  File "C:\Python\lib\encodings\cp1252.py", line 19, in encode
    return codecs.charmap_encode(input,self.errors,encoding_table)[0]
UnicodeEncodeError: 'charmap' codec can't encode characters in position 19-38: character maps to <undefined>

During handling of the above exception, another exception occurred:

Traceback (most recent call last):
  File "C:\Users\NKYA\Josiah_projects\Venv\afyaAI\lib\site-packages\django\core\handlers\exception.py", line 47, in inner
    response = get_response(request)
  File "C:\Users\NKYA\Josiah_projects\Venv\afyaAI\lib\site-packages\django\core\handlers\base.py", line 181, in _get_response
    response = wrapped_callback(request, *callback_args, **callback_kwargs)
  File "C:\Users\NKYA\Josiah_projects\Venv\afyaAI\lib\site-packages\django\views\decorators\csrf.py", line 54, in wrapped_view
    return view_func(*args, **kwargs)
  File "C:\Users\NKYA\Josiah_projects\CANCER\main\views.py", line 97, in upload_and_predict
    })
NameError: name 'logger' is not defined
Internal Server Error: /upload-and-predict/
Traceback (most recent call last):
  File "C:\Users\NKYA\Josiah_projects\CANCER\main\views.py", line 82, in upload_and_predict
    return JsonResponse({'error': 'Error processing the DICOM image'}, status=400)
  File "C:\Users\NKYA\Josiah_projects\Venv\afyaAI\lib\site-packages\keras\src\utils\traceback_utils.py", line 122, in error_handler
    raise e.with_traceback(filtered_tb) from None
  File "C:\Python\lib\encodings\cp1252.py", line 19, in encode
    return codecs.charmap_encode(input,self.errors,encoding_table)[0]
UnicodeEncodeError: 'charmap' codec can't encode characters in position 19-38: character maps to <undefined>

During handling of the above exception, another exception occurred:

Traceback (most recent call last):
  File "C:\Users\NKYA\Josiah_projects\Venv\afyaAI\lib\site-packages\django\core\handlers\exception.py", line 47, in inner
    response = get_response(request)
  File "C:\Users\NKYA\Josiah_projects\Venv\afyaAI\lib\site-packages\django\core\handlers\base.py", line 181, in _get_response
    response = wrapped_callback(request, *callback_args, **callback_kwargs)
  File "C:\Users\NKYA\Josiah_projects\Venv\afyaAI\lib\site-packages\django\views\decorators\csrf.py", line 54, in wrapped_view
    return view_func(*args, **kwargs)
  File "C:\Users\NKYA\Josiah_projects\CANCER\main\views.py", line 97, in upload_and_predict
    })
NameError: name 'logger' is not defined
"POST /upload-and-predict/ HTTP/1.1" 500 90643
"POST /upload-and-predict/ HTTP/1.1" 500 90934
"POST /upload-and-predict/ HTTP/1.1" 500 90934
Internal Server Error: /upload-and-predict/
"POST /upload-and-predict/ HTTP/1.1" 500 34
Internal Server Error: /upload-and-predict/
"POST /upload-and-predict/ HTTP/1.1" 500 34
Internal Server Error: /upload-and-predict/
"POST /upload-and-predict/ HTTP/1.1" 500 34
